Workbook

Sheet 2015-2019
A1: 住院号 | B1: 性别 | C1: 入区日期 | D1: 出院时间 | E1: 年龄 | F1: 影像号 | G1: MRI数量 | H1: CT数量 | I1: 脱敏 | J1: 是否有MRI | K1: 是否有CT | L1: 同时有MRI和CT | M1: 备注
A2: 0811290 | B2: 男 | C2: 2015010414:33:03 | D2: 2015010909:00:00 | E2: 24岁 | J2: =IF(G2>0,1,0) -> 0 | K2: =IF(H2>0,1,0) -> 0 | L2: =IF(G2>0,IF(H2>0,1,0),0) -> 0
A3: 0815164 | B3: 男 | C3: 2015010509:36:56 | D3: 2015011109:00:00 | E3: 20岁 | J3: =IF(G3>0,1,0) -> 0 | K3: =IF(H3>0,1,0) -> 0 | L3: =IF(G3>0,IF(H3>0,1,0),0) -> 0
A4: 0815366 | B4: 男 | C4: 2015010513:06:11 | D4: 2015011016:00:00 | E4: 18岁 | J4: =IF(G4>0,1,0) -> 0 | K4: =IF(H4>0,1,0) -> 0 | L4: =IF(G4>0,IF(H4>0,1,0),0) -> 0
A5: 0815511 | B5: 男 | C5: 2015010515:22:04 | D5: 2015010916:00:00 | E5: 30岁 | J5: =IF(G5>0,1,0) -> 0 | K5: =IF(H5>0,1,0) -> 0 | L5: =IF(G5>0,IF(H5>0,1,0),0) -> 0
A6: 0811352 | B6: 男 | C6: 2015010522:16:14 | D6: 2015010916:00:00 | E6: 22岁 | J6: =IF(G6>0,1,0) -> 0 | K6: =IF(H6>0,1,0) -> 0 | L6: =IF(G6>0,IF(H6>0,1,0),0) -> 0
A7: 0815469 | B7: 男 | C7: 2015010610:02:10 | D7: 2015011316:00:00 | E7: 23岁 | J7: =IF(G7>0,1,0) -> 0 | K7: =IF(H7>0,1,0) -> 0 | L7: =IF(G7>0,IF(H7>0,1,0),0) -> 0
A8: 0815687 | B8: 男 | C8: 2015010709:04:12 | D8: 2015011216:00:00 | E8: 29岁 | J8: =IF(G8>0,1,0) -> 0 | K8: =IF(H8>0,1,0) -> 0 | L8: =IF(G8>0,IF(H8>0,1,0),0) -> 0
A9: 0815959 | B9: 男 | C9: 2015010714:25:46 | D9: 2015011216:00:00 | E9: 41岁 | J9: =IF(G9>0,1,0) -> 0 | K9: =IF(H9>0,1,0) -> 0 | L9: =IF(G9>0,IF(H9>0,1,0),0) -> 0
A10: 0815978 | B10: 男 | C10: 2015010715:35:35 | D10: 2015011216:00:00 | E10: 33岁 | J10: =IF(G10>0,1,0) -> 0 | K10: =IF(H10>0,1,0) -> 0 | L10: =IF(G10>0,IF(H10>0,1,0),0) -> 0
A11: 0815986 | B11: 男 | C11: 2015010808:19:10 | D11: 2015011309:00:00 | E11: 49岁 | J11: =IF(G11>0,1,0) -> 0 | K11: =IF(H11>0,1,0) -> 0 | L11: =IF(G11>0,IF(H11>0,1,0),0) -> 0
A12: 0816017 | B12: 男 | C12: 2015010811:54:09 | D12: 2015012816:00:00 | E12: 24岁 | J12: =IF(G12>0,1,0) -> 0 | K12: =IF(H12>0,1,0) -> 0 | L12: =IF(G12>0,IF(H12>0,1,0),0) -> 0
A13: 0816459 | B13: 男 | C13: 2015010915:30:55 | D13: 2015011516:00:00 | E13: 35岁 | J13: =IF(G13>0,1,0) -> 0 | K13: =IF(H13>0,1,0) -> 0 | L13: =IF(G13>0,IF(H13>0,1,0),0) -> 0
... A561: 1027008 | B561: 女 | C561: 2016042914:32:34 | D561: 2016050715:28:42 | E561: 30岁 | J561: =IF(G561>0,1,0) -> 0 | K561: =IF(H561>0,1,0) -> 0 | L561: =IF(G561>0,IF(H561>0,1,0),0) -> 0
A562: 1027211 | B562: 男 | C562: 2016042915:32:25 | D562: 2016050413:01:49 | E562: 29岁 | J562: =IF(G562>0,1,0) -> 0 | K562: =IF(H562>0,1,0) -> 0 | L562: =IF(G562>0,IF(H562>0,1,0),0) -> 0
A563: 1027193 | B563: 男 | C563: 2016050415:39:10 | D563: 2016050714:16:47 | E563: 23岁 | J563: =IF(G563>0,1,0) -> 0 | K563: =IF(H563>0,1,0) -> 0 | L563: =IF(G563>0,IF(H563>0,1,0),0) -> 0
A564: 1033741 | B564: 男 | C564: 2016060308:08:51 | D564: 2016060908:30:36 | E564: 27岁 | J564: =IF(G564>0,1,0) -> 0 | K564: =IF(H564>0,1,0) -> 0 | L564: =IF(G564>0,IF(H564>0,1,0),0) -> 0
A565: 1023676 | B565: 男 | C565: 2016060515:22:34 | D565: 2016061014:25:46 | E565: 39岁 | J565: =IF(G565>0,1,0) -> 0 | K565: =IF(H565>0,1,0) -> 0 | L565: =IF(G565>0,IF(H565>0,1,0),0) -> 0
A566: 1023943 | B566: 女 | C566: 2016061107:33:51 | D566: 2016061613:45:48 | E566: 35岁 | J566: =IF(G566>0,1,0) -> 0 | K566: =IF(H566>0,1,0) -> 0 | L566: =IF(G566>0,IF(H566>0,1,0),0) -> 0
A567: 1041355 | B567: 男 | C567: 2016071314:46:13 | D567: 2016071614:28:48 | E567: 16岁 | J567: =IF(G567>0,1,0) -> 0 | K567: =IF(H567>0,1,0) -> 0 | L567: =IF(G567>0,IF(H567>0,1,0),0) -> 0
A568: 1041254 | B568: 男 | C568: 2016071316:24:00 | D568: 2016073008:44:49 | E568: 39岁 | J568: =IF(G568>0,1,0) -> 0 | K568: =IF(H568>0,1,0) -> 0 | L568: =IF(G568>0,IF(H568>0,1,0),0) -> 0
A569: 1026025 | B569: 男 | C569: 2016071919:54:24 | D569: 2016072408:32:55 | E569: 26岁 | J569: =IF(G569>0,1,0) -> 0 | K569: =IF(H569>0,1,0) -> 0 | L569: =IF(G569>0,IF(H569>0,1,0),0) -> 0
A570: 1047133 | B570: 男 | C570: 2016072715:57:06 | D570: 2016073013:43:13 | E570: 44岁 | J570: =IF(G570>0,1,0) -> 0 | K570: =IF(H570>0,1,0) -> 0 | L570: =IF(G570>0,IF(H570>0,1,0),0) -> 0
A571: 1026705 | B571: 男 | C571: 2016073115:40:04 | D571: 2016080514:01:18 | E571: 21岁 | J571: =IF(G571>0,1,0) -> 0 | K571: =IF(H571>0,1,0) -> 0 | L571: =IF(G571>0,IF(H571>0,1,0),0) -> 0
A572: 1048385 | B572: 男 | C572: 2016080415:34:56 | D572: 2016080913:43:04 | E572: 49岁 | J572: =IF(G572>0,1,0) -> 0 | K572: =IF(H572>0,1,0) -> 0 | L572: =IF(G572>0,IF(H572>0,1,0),0) -> 0
A573: 1045050 | B573: 男 | C573: 2016082617:59:45 | D573: 2016083113:28:53 | E573: 26岁 | J573: =IF(G573>0,1,0) -> 0 | K573: =IF(H573>0,1,0) -> 0 | L573: =IF(G573>0,IF(H573>0,1,0),0) -> 0
A574: 1045210 | B574: 男 | C574: 2016082813:59:24 | D574: 2016090309:00:39 | E574: 28岁 | J574: =IF(G574>0,1,0) -> 0 | K574: =IF(H574>0,1,0) -> 0 | L574: =IF(G574>0,IF(H574>0,1,0),0) -> 0
A575: 1045212 | B575: 男 | C575: 2016082814:34:22 | D575: 2016090213:45:19 | E575: 43岁 | J575: =IF(G575>0,1,0) -> 0 | K575: =IF(H575>0,1,0) -> 0 | L575: =IF(G575>0,IF(H575>0,1,0),0) -> 0
A576: 1045199 | B576: 男 | C576: 2016082814:52:10 | D576: 2016090213:31:52 | E576: 37岁 | J576: =IF(G576>0,1,0) -> 0 | K576: =IF(H576>0,1,0) -> 0 | L576: =IF(G576>0,IF(H576>0,1,0),0) -> 0
... A649: 1069261 | B649: 男 | C649: 2016110413:35:50 | D649: 2016111108:45:20 | E649: 45岁 | J649: =IF(G649>0,1,0) -> 0 | K649: =IF(H649>0,1,0) -> 0 | L649: =IF(G649>0,IF(H649>0,1,0),0) -> 0
A650: 1064996 | B650: 女 | C650: 2016110506:15:06 | D650: 2016110814:15:14 | E650: 34岁 | J650: =IF(G650>0,1,0) -> 0 | K650: =IF(H650>0,1,0) -> 0 | L650: =IF(G650>0,IF(H650>0,1,0),0) -> 0
A651: 1069761 | B651: 女 | C651: 2016110709:58:23 | D651: 2016111514:04:39 | E651: 18岁 | J651: =IF(G651>0,1,0) -> 0 | K651: =IF(H651>0,1,0) -> 0 | L651: =IF(G651>0,IF(H651>0,1,0),0) -> 0
A652: 1069996 | B652: 男 | C652: 2016110914:49:24 | D652: 2016111509:18:04 | E652: 33岁 | J652: =IF(G652>0,1,0) -> 0 | K652: =IF(H652>0,1,0) -> 0 | L652: =IF(G652>0,IF(H652>0,1,0),0) -> 0
A653: 1065263 | B653: 男 | C653: 2016110920:52:10 | D653: 2016111413:39:00 | E653: 40岁 | J653: =IF(G653>0,1,0) -> 0 | K653: =IF(H653>0,1,0) -> 0 | L653: =IF(G653>0,IF(H653>0,1,0),0) -> 0
A654: 1068152 | B654: 男 | C654: 2016111109:39:49 | D654: 2016111613:09:52 | E654: 24岁 | J654: =IF(G654>0,1,0) -> 0 | K654: =IF(H654>0,1,0) -> 0 | L654: =IF(G654>0,IF(H654>0,1,0),0) -> 0
A655: 1068219 | B655: 女 | C655: 2016111115:35:52 | D655: 2016111711:24:56 | E655: 34岁 | J655: =IF(G655>0,1,0) -> 0 | K655: =IF(H655>0,1,0) -> 0 | L655: =IF(G655>0,IF(H655>0,1,0),0) -> 0
A656: 1065488 | B656: 女 | C656: 2016111313:44:48 | D656: 2016111808:36:17 | E656: 45岁 | J656: =IF(G656>0,1,0) -> 0 | K656: =IF(H656>0,1,0) -> 0 | L656: =IF(G656>0,IF(H656>0,1,0),0) -> 0
A657: 1065430 | B657: 女 | C657: 2016111314:30:01 | D657: 2016111808:46:47 | E657: 32岁 | J657: =IF(G657>0,1,0) -> 0 | K657: =IF(H657>0,1,0) -> 0 | L657: =IF(G657>0,IF(H657>0,1,0),0) -> 0
A658: 1065491 | B658: 男 | C658: 2016111314:42:25 | D658: 2016111813:06:52 | E658: 24岁 | J658: =IF(G658>0,1,0) -> 0 | K658: =IF(H658>0,1,0) -> 0 | L658: =IF(G658>0,IF(H658>0,1,0),0) -> 0
A659: 1065492 | B659: 男 | C659: 2016111315:10:21 | D659: 2016111813:28:22 | E659: 31岁 | J659: =IF(G659>0,1,0) -> 0 | K659: =IF(H659>0,1,0) -> 0 | L659: =IF(G659>0,IF(H659>0,1,0),0) -> 0
...

Sheet 2020-2024.8
A1: 住院号 | B1: 性别 | C1: 入区日期 | D1: 出院时间 | E1: 年龄 | F1: 影像号 | G1: MRI数量 | H1: CT数量 | I1: 脱敏 | J1: 是否有MRI | K1: 是否有CT | L1: 同时有MRI和CT | M1: 备注
A2: 1379169 | B2: 男 | C2: 2020010115:28:16 | D2: 2020010614:37:30 | E2: 23岁 | F2: 4848271 | G2: 1 | H2: 0 | I2: 1 | J2: =IF(G2>0,1,0) -> 1 | K2: =IF(H2>0,1,0) -> 0 | L2: =IF(G2>0,IF(H2>0,1,0),0) -> 0
A3: 1379644 | B3: 女 | C3: 2020010221:01:15 | D3: 2020010709:40:15 | E3: 36岁 | F3: 4980715 | G3: 1 | H3: 0 | I3: 1 | J3: =IF(G3>0,1,0) -> 1 | K3: =IF(H3>0,1,0) -> 0 | L3: =IF(G3>0,IF(H3>0,1,0),0) -> 0
A4: 1380037 | B4: 男 | C4: 2020010318:45:32 | D4: 2020010908:56:35 | E4: 26岁 | F4: 4981817 | G4: 1 | H4: 0 | I4: 1 | J4: =IF(G4>0,1,0) -> 1 | K4: =IF(H4>0,1,0) -> 0 | L4: =IF(G4>0,IF(H4>0,1,0),0) -> 0
A5: 1380405 | B5: 男 | C5: 2020010514:21:49 | D5: 2020011114:21:39 | E5: 19岁 | F5: 4950245 | G5: 1 | H5: 1 | I5: 1 | J5: =IF(G5>0,1,0) -> 1 | K5: =IF(H5>0,1,0) -> 1 | L5: =IF(G5>0,IF(H5>0,1,0),0) -> 1
A6: 1380440 | B6: 男 | C6: 2020010516:40:45 | D6: 2020011009:21:44 | E6: 25岁 | F6: 4982606 | G6: 1 | H6: 0 | I6: 1 | J6: =IF(G6>0,1,0) -> 1 | K6: =IF(H6>0,1,0) -> 0 | L6: =IF(G6>0,IF(H6>0,1,0),0) -> 0
A7: 1381666 | B7: 男 | C7: 2020010814:56:32 | D7: 2020011313:16:20 | E7: 38岁 | F7: 3490861 | G7: 1 | H7: 0 | I7: 1 | J7: =IF(G7>0,1,0) -> 1 | K7: =IF(H7>0,1,0) -> 0 | L7: =IF(G7>0,IF(H7>0,1,0),0) -> 0
A8: 1381841 | B8: 男 | C8: 2020010909:28:00 | D8: 2020011313:17:58 | E8: 19岁 | F8: 4922991 | G8: 1 | H8: 1 | I8: 1 | J8: =IF(G8>0,1,0) -> 1 | K8: =IF(H8>0,1,0) -> 1 | L8: =IF(G8>0,IF(H8>0,1,0),0) -> 1
A9: 1382135 | B9: 男 | C9: 2020010917:51:01 | D9: 2020011613:22:03 | E9: 24岁 | F9: 4361253 | G9: 1 | H9: 0 | I9: 1 | J9: =IF(G9>0,1,0) -> 1 | K9: =IF(H9>0,1,0) -> 0 | L9: =IF(G9>0,IF(H9>0,1,0),0) -> 0
A10: 1382242 | B10: 男 | C10: 2020011008:55:43 | D10: 2020011513:31:21 | E10: 36岁 | F10: 4909776 | G10: 1 | H10: 0 | I10: 1 | J10: =IF(G10>0,1,0) -> 1 | K10: =IF(H10>0,1,0) -> 0 | L10: =IF(G10>0,IF(H10>0,1,0),0) -> 0
A11: 1382792 | B11: 男 | C11: 2020011115:11:33 | D11: 2020011814:04:34 | E11: 17岁 | F11: 4988237 | G11: 1 | H11: 1 | I11: 1 | J11: =IF(G11>0,1,0) -> 1 | K11: =IF(H11>0,1,0) -> 1 | L11: =IF(G11>0,IF(H11>0,1,0),0) -> 1
A12: 1382984 | B12: 男 | C12: 2020011214:31:36 | D12: 2020011814:23:52 | E12: 18岁 | F12: 4988238 | G12: 1 | H12: 0 | I12: 1 | J12: =IF(G12>0,1,0) -> 1 | K12: =IF(H12>0,1,0) -> 0 | L12: =IF(G12>0,IF(H12>0,1,0),0) -> 0
A13: 1382986 | B13: 男 | C13: 2020011214:31:25 | D13: 2020011613:35:47 | E13: 20岁 | F13: 4988239 | G13: 1 | H13: 0 | I13: 1 | J13: =IF(G13>0,1,0) -> 1 | K13: =IF(H13>0,1,0) -> 0 | L13: =IF(G13>0,IF(H13>0,1,0),0) -> 0
... A25: 1391561 | B25: 男 | C25: 2020031910:48:04 | D25: 2020032613:14:01 | E25: 35岁 | F25: 4980159 | G25: 0 | H25: 1 | I25: 1 | J25: =IF(G25>0,1,0) -> 0 | K25: =IF(H25>0,1,0) -> 1 | L25: =IF(G25>0,IF(H25>0,1,0),0) -> 0
A26: 1392025 | B26: 男 | C26: 2020032213:51:59 | D26: 2020032808:40:21 | E26: 37岁 | F26: 5015005 | G26: 0 | H26: 0 | I26: 0 | J26: =IF(G26>0,1,0) -> 0 | K26: =IF(H26>0,1,0) -> 0 | L26: =IF(G26>0,IF(H26>0,1,0),0) -> 0 | M26: 0
A27: 1392026 | B27: 女 | C27: 2020032214:00:24 | D27: 2020032813:23:45 | E27: 61岁 | F27: 4913968 | G27: 1 | H27: 0 | I27: 1 | J27: =IF(G27>0,1,0) -> 1 | K27: =IF(H27>0,1,0) -> 0 | L27: =IF(G27>0,IF(H27>0,1,0),0) -> 0
A28: 1392037 | B28: 男 | C28: 2020032214:32:55 | D28: 2020032808:54:42 | E28: 37岁 | F28: 4711019 | G28: 1 | H28: 0 | I28: 1 | J28: =IF(G28>0,1,0) -> 1 | K28: =IF(H28>0,1,0) -> 0 | L28: =IF(G28>0,IF(H28>0,1,0),0) -> 0
A29: 1392043 | B29: 男 | C29: 2020032214:46:24 | D29: 2020032813:38:06 | E29: 36岁 | F29: 4601053 | G29: 1 | H29: 0 | I29: 1 | J29: =IF(G29>0,1,0) -> 1 | K29: =IF(H29>0,1,0) -> 0 | L29: =IF(G29>0,IF(H29>0,1,0),0) -> 0
A30: 1392047 | B30: 女 | C30: 2020032215:04:49 | D30: 2020032813:42:48 | E30: 60岁 | F30: 5014957 | G30: 1 | H30: 1 | I30: 1 | J30: =IF(G30>0,1,0) -> 1 | K30: =IF(H30>0,1,0) -> 1 | L30: =IF(G30>0,IF(H30>0,1,0),0) -> 1
A31: 1392052 | B31: 男 | C31: 2020032215:36:09 | D31: 2020032814:44:17 | E31: 31岁 | F31: 5015006 | G31: 0 | H31: 0 | I31: 0 | J31: =IF(G31>0,1,0) -> 0 | K31: =IF(H31>0,1,0) -> 0 | L31: =IF(G31>0,IF(H31>0,1,0),0) -> 0 | M31: 0
A32: 1392278 | B32: 女 | C32: 2020032314:11:55 | D32: 2020033113:14:53 | E32: 51岁 | F32: 1421441 | G32: 1 | H32: 1 | I32: 1 | J32: =IF(G32>0,1,0) -> 1 | K32: =IF(H32>0,1,0) -> 1 | L32: =IF(G32>0,IF(H32>0,1,0),0) -> 1
A33: 1392319 | B33: 女 | C33: 2020032314:59:33 | D33: 2020040113:57:05 | E33: 16岁 | F33: 4368744 | G33: 1 | H33: 1 | I33: 1 | J33: =IF(G33>0,1,0) -> 1 | K33: =IF(H33>0,1,0) -> 1 | L33: =IF(G33>0,IF(H33>0,1,0),0) -> 1
A34: 1392372 | B34: 男 | C34: 2020032320:01:19 | D34: 2020032813:26:07 | E34: 32岁 | F34: 5015920 | G34: 0 | H34: 0 | I34: 0 | J34: =IF(G34>0,1,0) -> 0 | K34: =IF(H34>0,1,0) -> 0 | L34: =IF(G34>0,IF(H34>0,1,0),0) -> 0 | M34: 0
A35: 1392374 | B35: 女 | C35: 2020032320:26:19 | D35: 2020033010:40:30 | E35: 15岁 | F35: 5015888 | G35: 1 | H35: 0 | I35: 1 | J35: =IF(G35>0,1,0) -> 1 | K35: =IF(H35>0,1,0) -> 0 | L35: =IF(G35>0,IF(H35>0,1,0),0) -> 0
A36: 1392421 | B36: 女 | C36: 2020032408:46:33 | D36: 2020033013:15:06 | E36: 30岁 | F36: 4962357 | G36: 1 | H36: 0 | I36: 1 | J36: =IF(G36>0,1,0) -> 1 | K36: =IF(H36>0,1,0) -> 0 | L36: =IF(G36>0,IF(H36>0,1,0),0) -> 0
A37: 1392597 | B37: 女 | C37: 2020032415:58:00 | D37: 2020033112:39:56 | E37: 30岁 | F37: 5016686 | G37: 0 | H37: 0 | I37: 0 | J37: =IF(G37>0,1,0) -> 0 | K37: =IF(H37>0,1,0) -> 0 | L37: =IF(G37>0,IF(H37>0,1,0),0) -> 0 | M37: 0
A38: 1392978 | B38: 男 | C38: 2020032614:27:28 | D38: 2020040710:11:16 | E38: 29岁 | F38: 5019079 | G38: 0 | H38: 0 | I38: 0 | J38: =IF(G38>0,1,0) -> 0 | K38: =IF(H38>0,1,0) -> 0 | L38: =IF(G38>0,IF(H38>0,1,0),0) -> 0 | M38: 0
A39: 1393336 | B39: 女 | C39: 2020032813:58:23 | D39: 2020033013:26:49 | E39: 40岁 | F39: 2621343 | G39: 0 | H39: 0 | I39: 0 | J39: =IF(G39>0,1,0) -> 0 | K39: =IF(H39>0,1,0) -> 0 | L39: =IF(G39>0,IF(H39>0,1,0),0) -> 0 | M39: 0
A40: 1393438 | B40: 女 | C40: 2020032911:44:01 | D40: 2020040408:05:38 | E40: 36岁 | F40: 1786150 | G40: 1 | H40: 0 | I40: 1 | J40: =IF(G40>0,1,0) -> 1 | K40: =IF(H40>0,1,0) -> 0 | L40: =IF(G40>0,IF(H40>0,1,0),0) -> 0
A41: 1393455 | B41: 女 | C41: 2020032913:59:26 | D41: 2020040812:31:21 | E41: 50岁 | F41: 4999077 | G41: 1 | H41: 1 | I41: 1 | J41: =IF(G41>0,1,0) -> 1 | K41: =IF(H41>0,1,0) -> 1 | L41: =IF(G41>0,IF(H41>0,1,0),0) -> 1
A42: 1393472 | B42: 男 | C42: 2020032915:22:55 | D42: 2020040410:45:45 | E42: 27岁 | F42: 5019371 | G42: 1 | H42: 0 | I42: 1 | J42: =IF(G42>0,1,0) -> 1 | K42: =IF(H42>0,1,0) -> 0 | L42: =IF(G42>0,IF(H42>0,1,0),0) -> 0
A43: 1393572 | B43: 男 | C43: 2020033010:47:22 | D43: 2020040609:35:16 | E43: 28岁 | F43: 5013808 | G43: 0 | H43: 0 | I43: 0 | J43: =IF(G43>0,1,0) -> 0 | K43: =IF(H43>0,1,0) -> 0 | L43: =IF(G43>0,IF(H43>0,1,0),0) -> 0 | M43: 0
A44: 1393742 | B44: 女 | C44: 2020033016:44:44 | D44: 2020040809:09:35 | E44: 15岁 | F44: 5020076 | G44: 1 | H44: 0 | I44: 1 | J44: =IF(G44>0,1,0) -> 1 | K44: =IF(H44>0,1,0) -> 0 | L44: =IF(G44>0,IF(H44>0,1,0),0) -> 0
A45: 1393999 | B45: 男 | C45: 2020033115:44:58 | D45: 2020040509:27:56 | E45: 33岁 | F45: 5012251 | G45: 1 | H45: 1 | I45: 1 | J45: =IF(G45>0,1,0) -> 1 | K45: =IF(H45>0,1,0) -> 1 | L45: =IF(G45>0,IF(H45>0,1,0),0) -> 1
A46: 1394184 | B46: 男 | C46: 2020040114:19:14 | D46: 2020040813:16:12 | E46: 26岁 | F46: 5021650 | G46: 1 | H46: 0 | I46: 1 | J46: =IF(G46>0,1,0) -> 1 | K46: =IF(H46>0,1,0) -> 0 | L46: =IF(G46>0,IF(H46>0,1,0),0) -> 0
A47: 1394501 | B47: 女 | C47: 2020040218:23:19 | D47: 2020041108:47:36 | E47: 43岁 | F47: 4946573 | G47: 0 | H47: 0 | I47: 0 | J47: =IF(G47>0,1,0) -> 0 | K47: =IF(H47>0,1,0) -> 0 | L47: =IF(G47>0,IF(H47>0,1,0),0) -> 0 | M47: 0
A48: 1394533 | B48: 男 | C48: 2020040308:14:14 | D48: 2020061710:55:39 | E48: 22岁 | F48: 4948006 | G48: 1 | H48: 0 | I48: 1 | J48: =IF(G48>0,1,0) -> 1 | K48: =IF(H48>0,1,0) -> 0 | L48: =IF(G48>0,IF(H48>0,1,0),0) -> 0
A49: 1394925 | B49: 男 | C49: 2020040610:11:30 | D49: 2020041209:37:57 | E49: 48岁 | F49: 5018976 | G49: 1 | H49: 1 | I49: 1 | J49: =IF(G49>0,1,0) -> 1 | K49: =IF(H49>0,1,0) -> 1 | L49: =IF(G49>0,IF(H49>0,1,0),0) -> 1
A50: 1394971 | B50: 男 | C50: 2020040612:03:20 | D50: 2020041213:24:27 | E50: 26岁 | F50: 5027030 | G50: 0 | H50: 0 | I50: 0 | J50: =IF(G50>0,1,0) -> 0 | K50: =IF(H50>0,1,0) -> 0 | L50: =IF(G50>0,IF(H50>0,1,0),0) -> 0 | M50: 0
A51: 1395007 | B51: 男 | C51: 2020040614:45:40 | D51: 2020041208:53:56 | E51: 26岁 | F51: 5024113 | G51: 1 | H51: 0 | I51: 1 | J51: =IF(G51>0,1,0) -> 1 | K51: =IF(H51>0,1,0) -> 0 | L51: =IF(G51>0,IF(H51>0,1,0),0) -> 0
...

Sheet 2024.9-
A1: 住院号 | B1: 性别 | C1: 入区日期 | D1: 出院时间 | E1: 年龄 | F1: 影像号 | G1: MRI数量 | H1: CT数量 | I1: 脱敏 | J1: 是否有MRI | K1: 是否有CT | L1: 同时有MRI和CT | M1: 备注
A2: 1956135 | B2: 男 | C2: 2024082415:23:39 | D2: 2024090109:00:00 | E2: 26岁 | F2: 6670083 | G2: 0 | H2: 0 | I2: 0 | J2: =IF(G2>0,1,0) -> 0 | K2: =IF(H2>0,1,0) -> 0 | L2: =IF(G2>0,IF(H2>0,1,0),0) -> 0 | M2: ACL翻修
A3: 1954910 | B3: 男 | C3: 2024082809:39:43 | D3: 2024090116:00:00 | E3: 17岁 | F3: 6666185 | G3: 1 | H3: 0 | I3: 1 | J3: =IF(G3>0,1,0) -> 1 | K3: =IF(H3>0,1,0) -> 0 | L3: =IF(G3>0,IF(H3>0,1,0),0) -> 0
A4: 1954950 | B4: 男 | C4: 2024082809:09:17 | D4: 2024090116:00:00 | E4: 31岁 | F4: 6666486 | G4: 1 | H4: 0 | I4: 1 | J4: =IF(G4>0,1,0) -> 1 | K4: =IF(H4>0,1,0) -> 0 | L4: =IF(G4>0,IF(H4>0,1,0),0) -> 0
A5: 1956849 | B5: 男 | C5: 2024082614:20:35 | D5: 2024090116:00:00 | E5: 20岁 | F5: 6671837 | G5: 1 | H5: 1 | I5: 1 | J5: =IF(G5>0,1,0) -> 1 | K5: =IF(H5>0,1,0) -> 1 | L5: =IF(G5>0,IF(H5>0,1,0),0) -> 1
A6: 1957899 | B6: 男 | C6: 2024082814:47:36 | D6: 2024090116:00:00 | E6: 33岁 | F6: 6663697 | G6: 1 | H6: 0 | I6: 1 | J6: =IF(G6>0,1,0) -> 1 | K6: =IF(H6>0,1,0) -> 0 | L6: =IF(G6>0,IF(H6>0,1,0),0) -> 0
A7: 1957977 | B7: 女 | C7: 2024082907:44:58 | D7: 2024090116:00:00 | E7: 40岁 | F7: 6628340 | G7: 1 | H7: 0 | I7: 1 | J7: =IF(G7>0,1,0) -> 1 | K7: =IF(H7>0,1,0) -> 0 | L7: =IF(G7>0,IF(H7>0,1,0),0) -> 0
A8: 1958380 | B8: 男 | C8: 2024082914:58:13 | D8: 2024090216:00:00 | E8: 41岁 | F8: 6676253 | G8: 0 | H8: 0 | I8: 0 | J8: =IF(G8>0,1,0) -> 0 | K8: =IF(H8>0,1,0) -> 0 | L8: =IF(G8>0,IF(H8>0,1,0),0) -> 0
A9: 1957433 | B9: 男 | C9: 2024082715:06:36 | D9: 2024090309:00:00 | E9: 39岁 | F9: 6672993 | G9: 1 | H9: 1 | I9: 1 | J9: =IF(G9>0,1,0) -> 1 | K9: =IF(H9>0,1,0) -> 1 | L9: =IF(G9>0,IF(H9>0,1,0),0) -> 1
A10: 1957765 | B10: 男 | C10: 2024082813:27:34 | D10: 2024090316:00:00 | E10: 17岁 | F10: 6674356 | G10: 1 | H10: 1 | I10: 1 | J10: =IF(G10>0,1,0) -> 1 | K10: =IF(H10>0,1,0) -> 1 | L10: =IF(G10>0,IF(H10>0,1,0),0) -> 1
A11: 1957962 | B11: 男 | C11: 2024082816:11:48 | D11: 2024090316:00:00 | E11: 23岁 | F11: 6674355 | G11: 1 | H11: 1 | I11: 1 | J11: =IF(G11>0,1,0) -> 1 | K11: =IF(H11>0,1,0) -> 1 | L11: =IF(G11>0,IF(H11>0,1,0),0) -> 1
A12: 1956282 | B12: 女 | C12: 2024082512:11:03 | D12: 2024090409:00:00 | E12: 47岁 | F12: 6670377 | G12: 1 | H12: 0 | I12: 1 | J12: =IF(G12>0,1,0) -> 1 | K12: =IF(H12>0,1,0) -> 0 | L12: =IF(G12>0,IF(H12>0,1,0),0) -> 0
A13: 1958866 | B13: 男 | C13: 2024083015:26:10 | D13: 2024090409:00:00 | E13: 42岁 | F13: 4728754 | G13: 1 | H13: 0 | I13: 1 | J13: =IF(G13>0,1,0) -> 1 | K13: =IF(H13>0,1,0) -> 0 | L13: =IF(G13>0,IF(H13>0,1,0),0) -> 0
A14: 1958439 | B14: 男 | C14: 2024082915:48:53 | D14: 2024090412:03:25 | E14: 35岁 | F14: 6675771 | G14: 0 | H14: 0 | I14: 0 | J14: =IF(G14>0,1,0) -> 0 | K14: =IF(H14>0,1,0) -> 0 | L14: =IF(G14>0,IF(H14>0,1,0),0) -> 0
A15: 1959051 | B15: 女 | C15: 2024083112:11:40 | D15: 2024090416:00:00 | E15: 56岁 | F15: 6676929 | G15: 0 | H15: 1 | I15: 1 | J15: =IF(G15>0,1,0) -> 0 | K15: =IF(H15>0,1,0) -> 1 | L15: =IF(G15>0,IF(H15>0,1,0),0) -> 0 | M15: 右膝ACL、PCL、PMC
A16: 1959448 | B16: 男 | C16: 2024090115:10:58 | D16: 2024090416:00:00 | E16: 34岁 | F16: 6539376 | G16: 1 | H16: 0 | I16: 1 | J16: =IF(G16>0,1,0) -> 1 | K16: =IF(H16>0,1,0) -> 0 | L16: =IF(G16>0,IF(H16>0,1,0),0) -> 0
A17: 1959174 | B17: 男 | C17: 2024083114:58:45 | D17: 2024090514:00:00 | E17: 40岁 | F17: 6678171 | G17: 0 | H17: 0 | I17: 0 | J17: =IF(G17>0,1,0) -> 0 | K17: =IF(H17>0,1,0) -> 0 | L17: =IF(G17>0,IF(H17>0,1,0),0) -> 0
A18: 1959176 | B18: 男 | C18: 2024083114:56:38 | D18: 2024090514:00:00 | E18: 35岁 | F18: 6677847 | G18: 0 | H18: 0 | I18: 0 | J18: =IF(G18>0,1,0) -> 0 | K18: =IF(H18>0,1,0) -> 0 | L18: =IF(G18>0,IF(H18>0,1,0),0) -> 0
A19: 1959536 | B19: 男 | C19: 2024090214:46:46 | D19: 2024090609:00:00 | E19: 55岁 | F19: 6680306 | G19: 0 | H19: 0 | I19: 0 | J19: =IF(G19>0,1,0) -> 0 | K19: =IF(H19>0,1,0) -> 0 | L19: =IF(G19>0,IF(H19>0,1,0),0) -> 0
A20: 1960192 | B20: 男 | C20: 2024090408:31:36 | D20: 2024090609:00:00 | E20: 29岁 | F20: 6679622 | G20: 1 | H20: 0 | I20: 1 | J20: =IF(G20>0,1,0) -> 1 | K20: =IF(H20>0,1,0) -> 0 | L20: =IF(G20>0,IF(H20>0,1,0),0) -> 0
A21: 1960616 | B21: 男 | C21: 2024090411:56:42 | D21: 2024090611:51:59 | E21: 42岁 | F21: 6680812 | G21: 1 | H21: 0 | I21: 1 | J21: =IF(G21>0,1,0) -> 1 | K21: =IF(H21>0,1,0) -> 0 | L21: =IF(G21>0,IF(H21>0,1,0),0) -> 0
A22: 1958803 | B22: 男 | C22: 2024083014:53:42 | D22: 2024090716:00:00 | E22: 38岁 | F22: 6676543 | G22: 1 | H22: 1 | I22: 1 | J22: =IF(G22>0,1,0) -> 1 | K22: =IF(H22>0,1,0) -> 1 | L22: =IF(G22>0,IF(H22>0,1,0),0) -> 1
A23: 1958842 | B23: 男 | C23: 2024083014:51:15 | D23: 2024090716:00:00 | E23: 27岁 | F23: 6645538 | G23: 1 | H23: 1 | I23: 1 | J23: =IF(G23>0,1,0) -> 1 | K23: =IF(H23>0,1,0) -> 1 | L23: =IF(G23>0,IF(H23>0,1,0),0) -> 1
A24: 1959202 | B24: 男 | C24: 2024083115:46:02 | D24: 2024090809:00:00 | E24: 25岁 | F24: 6631197 | G24: 1 | H24: 1 | I24: 1 | J24: =IF(G24>0,1,0) -> 1 | K24: =IF(H24>0,1,0) -> 1 | L24: =IF(G24>0,IF(H24>0,1,0),0) -> 1
A25: 1960213 | B25: 女 | C25: 2024090310:37:12 | D25: 2024090809:00:00 | E25: 46岁 | F25: 6680366 | G25: 0 | H25: 0 | I25: 0 | J25: =IF(G25>0,1,0) -> 0 | K25: =IF(H25>0,1,0) -> 0 | L25: =IF(G25>0,IF(H25>0,1,0),0) -> 0 | M25: 右膝ACL止点
A26: 1951096 | B26: 男 | C26: 2024090409:39:32 | D26: 2024090816:00:00 | E26: 29岁 | F26: 6656795 | G26: 0 | H26: 0 | I26: 0 | J26: =IF(G26>0,1,0) -> 0 | K26: =IF(H26>0,1,0) -> 0 | L26: =IF(G26>0,IF(H26>0,1,0),0) -> 0 | M26: 左膝ACL、PCL
A27: 1956732 | B27: 男 | C27: 2024090613:59:00 | D27: 2024090816:00:00 | E27: 59岁 | F27: 5103121 | G27: 1 | H27: 0 | I27: 1 | J27: =IF(G27>0,1,0) -> 1 | K27: =IF(H27>0,1,0) -> 0 | L27: =IF(G27>0,IF(H27>0,1,0),0) -> 0
A28: 1960340 | B28: 女 | C28: 2024090313:44:35 | D28: 2024090816:00:00 | E28: 46岁 | F28: 6674422 | G28: 1 | H28: 1 | I28: 1 | J28: =IF(G28>0,1,0) -> 1 | K28: =IF(H28>0,1,0) -> 1 | L28: =IF(G28>0,IF(H28>0,1,0),0) -> 1
A29: 1960403 | B29: 男 | C29: 2024090508:15:54 | D29: 2024090816:00:00 | E29: 56岁 | F29: 6680397 | G29: 1 | H29: 0 | I29: 1 | J29: =IF(G29>0,1,0) -> 1 | K29: =IF(H29>0,1,0) -> 0 | L29: =IF(G29>0,IF(H29>0,1,0),0) -> 0
A30: 1960499 | B30: 男 | C30: 2024090316:26:22 | D30: 2024090816:00:00 | E30: 52岁 | F30: 6676114 | G30: 1 | H30: 1 | I30: 1 | J30: =IF(G30>0,1,0) -> 1 | K30: =IF(H30>0,1,0) -> 1 | L30: =IF(G30>0,IF(H30>0,1,0),0) -> 1
A31: 1960506 | B31: 男 | C31: 2024090411:07:34 | D31: 2024090816:00:00 | E31: 24岁 | F31: 6680606 | G31: 1 | H31: 0 | I31: 1 | J31: =IF(G31>0,1,0) -> 1 | K31: =IF(H31>0,1,0) -> 0 | L31: =IF(G31>0,IF(H31>0,1,0),0) -> 0
A32: 1960642 | B32: 男 | C32: 2024090413:46:38 | D32: 2024090816:00:00 | E32: 30岁 | F32: 6680847 | G32: 1 | H32: 1 | I32: 1 | J32: =IF(G32>0,1,0) -> 1 | K32: =IF(H32>0,1,0) -> 1 | L32: =IF(G32>0,IF(H32>0,1,0),0) -> 1
A33: 1960825 | B33: 男 | C33: 2024090411:25:09 | D33: 2024090816:00:00 | E33: 42岁 | F33: 6682761 | G33: 0 | H33: 0 | I33: 0 | J33: =IF(G33>0,1,0) -> 0 | K33: =IF(H33>0,1,0) -> 0 | L33: =IF(G33>0,IF(H33>0,1,0),0) -> 0
A34: 1961214 | B34: 男 | C34: 2024090514:40:57 | D34: 2024090816:00:00 | E34: 29岁 | F34: 6682254 | G34: 0 | H34: 0 | I34: 0 | J34: =IF(G34>0,1,0) -> 0 | K34: =IF(H34>0,1,0) -> 0 | L34: =IF(G34>0,IF(H34>0,1,0),0) -> 0
A35: 1960320 | B35: 女 | C35: 2024090511:59:06 | D35: 2024090909:00:00 | E35: 32岁 | F35: 5597271 | G35: 0 | H35: 0 | I35: 0 | J35: =IF(G35>0,1,0) -> 0 | K35: =IF(H35>0,1,0) -> 0 | L35: =IF(G35>0,IF(H35>0,1,0),0) -> 0
A36: 1961376 | B36: 男 | C36: 2024090513:51:34 | D36: 2024090914:00:00 | E36: 38岁 | F36: 6682949 | G36: 1 | H36: 1 | I36: 1 | J36: =IF(G36>0,1,0) -> 1 | K36: =IF(H36>0,1,0) -> 1 | L36: =IF(G36>0,IF(H36>0,1,0),0) -> 1
A37: 1961357 | B37: 男 | C37: 2024090513:45:38 | D37: 2024090916:00:00 | E37: 28岁 | F37: 6683265 | G37: 1 | H37: 0 | I37: 1 | J37: =IF(G37>0,1,0) -> 1 | K37: =IF(H37>0,1,0) -> 0 | L37: =IF(G37>0,IF(H37>0,1,0),0) -> 0
A38: 1961444 | B38: 男 | C38: 2024090514:33:09 | D38: 2024090916:00:00 | E38: 18岁 | G38: 0 | H38: 0 | I38: 0 | J38: =IF(G38>0,1,0) -> 0 | K38: =IF(H38>0,1,0) -> 0 | L38: =IF(G38>0,IF(H38>0,1,0),0) -> 0
A39: 1961446 | B39: 男 | C39: 2024090514:34:02 | D39: 2024090916:00:00 | E39: 22岁 | F39: 6683264 | G39: 0 | H39: 0 | I39: 0 | J39: =IF(G39>0,1,0) -> 0 | K39: =IF(H39>0,1,0) -> 0 | L39: =IF(G39>0,IF(H39>0,1,0),0) -> 0
A40: 1961518 | B40: 女 | C40: 2024090515:46:38 | D40: 2024090916:00:00 | E40: 49岁 | F40: 6683936 | G40: 0 | H40: 0 | I40: 0 | J40: =IF(G40>0,1,0) -> 0 | K40: =IF(H40>0,1,0) -> 0 | L40: =IF(G40>0,IF(H40>0,1,0),0) -> 0
...

Sheet Sheet1
